<?xml version="1.0" encoding="UTF-8" standalone="no"?>
<?xml-stylesheet type="text/xsl"  href="detail_result.xsl"?>
<TestResult>
<CaseInfo>
<CaseID name="S01001001"/>
<Description name="Demo failed case"/>
<Result name="fail"/>
<Duration name="6110 ms"/>
<Timeout name="10000"/>
<Type name="Default;"/>
<ErrorHandler name="&lt;class &apos;ErrorHandler.ErrorHandlers.DefaultErrorHandler&apos;&gt;"/>
<StartTime name="2017-02-23 18:02:39.518565"/>
<EndTime name="2017-02-23 18:02:45.628838"/>
<ErrorMessage name="Traceback (most recent call last):
  File &quot;C:\tools\TestFramework_5.0\framework\Runner.py&quot;, line 264, in run
    self.mFuncObj(self.mErrorHandler)
  File &quot;.\Cases\DemoTest.py&quot;, line 49, in S01001001
    raise Exception(&apos;Exception in S01001001!&apos;)
Exception: Exception in S01001001!
"/>
<TraceStack name=""/>
<Performance>
  <Proc name="python" pid="3812" detail=".\3812-python.html">
	<Category maximum="24.773438" average="24.773438"/>
	<Category maximum="265.000000" average="265.000000"/>
	<Category maximum="1.898393" average="1.898393"/>
  </Proc>
<Category>
	<Descrip name="Memory Usage (MB)"/>
	<Descrip name="Read I/O Count (Persec)"/>
	<Descrip name="Read I/O (MB/Sec)"/>
</Category>
</Performance>
</CaseInfo>
</TestResult>
